Workbook

Sheet Daily Report
B3: NEZ Today Branch Report Send BY BM Status Report
B4: Zone | C4: RegionID | D4: DistrictName | E4: TotalBranch | F4: Report_send_BY_BM | G4: Report_send_BY_BM% | H4: No of Client DUE | I4: TOTAL_DUE | J4: No of Clent_Disbursed | K4: TOTAL_Disbursed | L4: No of BC_Clent_Disbursed | M4: TOTAL BC_Amount_Disbursed | N4: No of OWN_Clent_Disbursed | O4: TOTAL OWN_Amount_Disbursed | P4: Disbursed Client % | Q4: Disbursed Amount %
A5: ADO | B5: HOT-North East Zone | C5: 21 | D5: MUZAFFARPUR | E5: 24 | F5: 0 | G5: 0 | H5: 433 | I5: 15636000 | J5: 175 | K5: 6360000 | L5: 8 | M5: 590000 | N5: 167 | O5: 5770000 | P5: 40 | Q5: 40.675365
B6: HOT-North East Zone | C6: 31 | D6: SITAMARHI&DARBHANGA | E6: 24 | F6: 0 | G6: 0 | H6: 406 | I6: 13254000 | J6: 143 | K6: 4796000 | L6: 0 | M6: NULL | N6: 143 | O6: 4796000 | P6: 35 | Q6: 36.185303
B7: HOT-NORTH EAST ZONE | C7: 35 | D7: SAMASTIPUR | E7: 18 | F7: 0 | G7: 0 | H7: 215 | I7: 6028000 | J7: 60 | K7: 1825000 | L7: 0 | M7: NULL | N7: 60 | O7: 1825000 | P7: 27 | Q7: 30.275382
D8: Total | E8: 0 | F8: =SUM(F5:F7) -> 0 | G8: 0 | H8: 0 | I8: 0 | J8: 0 | K8: 0 | L8: 0 | M8: 0 | N8: 0 | O8: 0 | P8: =+(N8+L8)/H8*100 -> #DIV/0! | Q8: =+(O8+M8)/I8*100 -> #DIV/0!
F9: =+E8-F8 -> 0
A10: DDO | B10: HOT-North East Zone | C10: 10 | D10: SARAN | E10: 24 | F10: 0 | G10: 0 | H10: 882 | I10: 31433000 | J10: 31 | K10: 1455000 | L10: 7 | M10: 620000 | N10: 24 | O10: 835000 | P10: 3 | Q10: 4.6288932
B11: HOT-North East Zone | C11: 14 | D11: SIWAN | E11: 24 | F11: 0 | G11: 0 | H11: 490 | I11: 16629000 | J11: 42 | K11: 1427000 | L11: 5 | M11: 280000 | N11: 37 | O11: 1147000 | P11: 8 | Q11: 8.581394
B12: HOT-North East Zone | C12: 22 | D12: EAST CHAMPARAN | E12: 24 | F12: 0 | G12: 0 | H12: 451 | I12: 16049000 | J12: 36 | K12: 1274000 | L12: 3 | M12: 260000 | N12: 33 | O12: 1014000 | P12: 7 | Q12: 7.9381893
D13: Total | E13: =SUM(E10:E12) -> 72 | F13: =SUM(F10:F12) -> 0 | G13: =SUM(G10:G12) -> 0 | H13: =SUM(H10:H12) -> 1823 | I13: =SUM(I10:I12) -> 64111000 | J13: =SUM(J10:J12) -> 109 | K13: =SUM(K10:K12) -> 4156000 | L13: =SUM(L10:L12) -> 15 | ... O13: =SUM(O10:O12) -> 2996000 | P13: =+(N13+L13)/H13*100 -> 5.9791552 | Q13: =+(O13+M13)/I13*100 -> 6.4825069
F14: =+E13-F13 -> 72
E15: Total Pending | F15: =+F14+F9 -> 72
B44: Today SIDBI Documentation Report
B45: RegionName | C45: NoofDue | D45: SIDBI Due AMT | E45: No of Disbursed | F45: SIDBI Disbursed AMT | G45: Client % | H45: Amt Doc % | I45: No of pending Doc
B46: Ballia | C46: 52 | D46: 5720000 | E46: 28 | F46: 2680000 | G46: 53 | H46: 46 | I46: 24
B47: Saran | C47: 40 | D47: 3520000 | E47: 20 | F47: 1850000 | G47: 50 | H47: 52 | I47: 20
B48: Siwan | C48: 66 | D48: 5180000 | E48: 49 | F48: 3860000 | G48: 74 | H48: 74 | I48: 17
B49: Muzaffarpur | C49: 49 | D49: 3510000 | E49: 29 | F49: 2120000 | G49: 59 | H49: 60 | I49: 20
B50: East Champaran | C50: 61 | D50: 4790000 | E50: 49 | F50: 3910000 | G50: 80 | H50: 81 | I50: 12
B51: Total | C51: =SUM(C46:C50) -> 268 | D51: =SUM(D46:D50) -> 22720000 | E51: =SUM(E46:E50) -> 175 | F51: =SUM(F46:F50) -> 14420000 | G51: =+E51/C51*100 -> 65.298507 | H51: =+F51/D51*100 -> 63.46831 | I51: =+C51-E51 -> 93

Sheet Pending Branch Day Close Report
A1: Pending Report | D1: Pending Report | G1: Pending Report | J1: Pending Report | M1: Pending Report
A2: Branchid | B2: BranchName | D2: Branchid | E2: BranchName | G2: Branchid | H2: BranchName | J2: Branchid | K2: BranchName | M2: Branchid | N2: BranchName
A3: 10:01 | B3: U-1(Manjhi) | D3: 35:01 | E3: TAJPUR | G3: 14:07 | H3: MaharajGanj | J3: 21:08 | K3: Sarfuddinpur | M3: 22:20 | N3: Jagdishpur
A4: 10:02 | B4: U-2(Bheldi) | D4: 35:02 | E4: UJIYARPUR | G4: 14:12 | H4: Ander | J4: 21:11 | K4: Kurhani | M4: 22:22 | N4: Mehasi
A5: 10:03 | B5: U-3(Essuapur) | D5: 35:03 | E5: SARAI RANJAN | G5: 14:14 | H5: Jamo | J5: 21:12 | K5: Bochahan | M5: 22:31 | N5: Pakadi Dayal
A6: 10:04 | B6: U-4(Maker) | D6: 35:04 | E6: SHIVAJI NAGAR | G6: 14:15 | H6: Duroundha | J6: 21:14 | K6: Dewariya | M6: 22:33 | N6: RamNagar
A7: 10:06 | B7: RivilGanj | D7: 35:06 | E7: BARAUNI | G7: 14:19 | H7: Ekma | J7: 21:16 | K7: Sakari Saraiya | M7: 22:35 | N7: Barauli
A8: 10:07 | B8: JalalPur | D8: 35:08 | E8: BACHWADA | G8: 14:20 | H8: Bhatani | J8: 21:18 | K8: Goraul
A9: 10:09 | B9: Masarkh | D9: 35:09 | E9: DALSINGH SARAI | G9: 14:21 | H9: Salempur | J9: 21:23 | K9: Baruari
A10: 10:11 | B10: Taraiya | D10: 35:10 | E10: KALYANPUR | G10: 14:22 | H10: Bhatpar | J10: 21:25 | K10: Hanuman Nagar
A11: 10:12 | B11: Parsa | D11: 35:11 | E11: VIDYAPATTI NAGAR | G11: 14:23 | H11: Lar Town | J11: 21:26 | K11: Bharwada
A12: 10:13 | B12: SonePur | D12: 35:12 | E12: KHANPUR | G12: 14:24 | H12: Hathuwa | J12: 21:27 | K12: Hayaghat
A13: 10:14 | B13: Sadar | D13: 35:13 | E13: BAHERI | G13: 14:25 | H13: Vijaipur | J13: 21:28 | K13: Jalle
A14: 10:15 | B14: DoriGanj | D14: 35:18 | E14: VIDUPUR | G14: 14:27 | H14: Majha
A15: 10:16 | B15: Dighawada | G15: 14:28 | H15: Haziyapur
A16: 10:17 | B16: Pateda | G16: 14:29 | H16: Thawe
A17: 10:21 | B17: Bairia
A18: 10:22 | B18: Rewati
A19: 10:23 | B19: Sahatwar
A20: 10:25 | B20: Paroo
A21: 10:26 | B21: Panapur

Sheet Sheet1
A1: StaffID | B1: StaffName | C1: StaffNameLocal | D1: ExitDate | E1: EntryBy | F1: DateStamp | G1: StatusAct | H1: FS_Type | I1: TelePhone | J1: Code | K1: TerminalID | L1: HRUpdationDate | M1: OwnPortfolioinLastMonth | N1: OwnALCinLastMonth | O1: BCPortfolioinLastMonth | P1: BCALCinLastMonth | Q1: FlexiPortfolioinLastMonth | R1: FlexiALCinLastMonth | S1: SavingClientinLastMonth | T1: PensionclientinLastMonth | U1: NonIGLPortfolioLastMonth | V1: NonIGLALCLastMonth | W1: LoanClientsLastFiscal | X1: OutstandingLastFiscal | Y1: PortfolioFTM | Z1: LoanClientsFTM | AA1: PARTargetfortheMonth | AB1: Aadharno | AC1: Bankname | AD1: Imeinumber | AE1: Mobilenumber | AF1: StaffMappedWith | AG1: appversion | AH1: staffappversion | AI1: Partarget
A2: 1517 | B2: Sangeeta | C2: a | D2: NULL | E2: 2130 | F2: 44592 | G2: 0 | H2: 0 | I2: 7459013702 | J2: 0 | K2: NULL | L2: NULL | M2: 0 | N2: 0 | O2: 0 | P2: 0 | Q2: 0 | R2: 0 | S2: 0 | T2: 0 | U2: 0 | V2: 0 | W2: 0 | X2: 0 | Y2: 350291 | Z2: 0 | AA2: 0 | AB2: NULL | AC2: NULL | AD2: 133eec7a-4dfc-40b4-b2ce-b25116c5af3a | AE2: 7459013702 | AG2: 1.2 | AH2: 1.2 | AI2: 1.902
A3: 13879 | B3: Poonam Kumari | C3: Poonam Kumari | D3: NULL | E3: 2130 | F3: 44590 | G3: 1 | H3: 0 | I3: 9110103633 | J3: 0 | K3: NULL | L3: NULL | M3: 0 | N3: 0 | O3: 0 | P3: 0 | Q3: 0 | R3: 0 | S3: 0 | T3: 0 | U3: 0 | V3: 0 | W3: NULL | X3: NULL | Y3: NULL | Z3: NULL | AA3: 0 | AB3: 781909136222 | AC3: 608112 | AD3: 5558d0b9-8f16-4e6d-b729-0248e40240f0 | AE3: 9110103633 | AG3: 1.2 | AH3: 1.2 | AI3: NULL
A4: 7715 | B4: Jitendra Bahadur Singh | C4: Jitendra Bahadur Singh | D4: NULL | E4: 828 | F4: 43980 | G4: 1 | H4: 0 | I4: 7905683569 | J4: 0 | K4: NULL | L4: NULL | M4: 0 | N4: 0 | O4: 0 | P4: 0 | Q4: 0 | R4: 0 | S4: 0 | T4: 33 | U4: 17627 | V4: 12 | W4: 457 | X4: 6909266 | Y4: 1132460 | Z4: 0 | AA4: 0 | AB4: NULL | AC4: NULL | AD4: 88c2802d-baa0-47aa-b383-a22ab28afd24 | AE4: 7905683569 | AF4: NULL | AG4: 1.2 | AH4: 1.2 | AI4: NULL
A5: 2755 | B5: SAILESH YADAV | C5: SAILESH YADAV | D5: NULL | E5: 9809 | F5: 44384 | G5: 1 | H5: 0 | I5: 8279767524 | J5: 0 | K5: NULL | L5: NULL | M5: 0 | N5: 0 | O5: 0 | P5: 0 | Q5: 0 | R5: 0 | S5: 0 | T5: 0 | U5: 0 | V5: 0 | W5: 0 | X5: 0 | Y5: 0 | Z5: 0 | AA5: 0 | AB5: NULL | AC5: NULL | AD5: 352980103376734 | AE5: 8279767524 | AG5: 1.2 | AH5: 1.2 | AI5: NULL
A6: 4366 | B6: Raj Kumar Bharati | C6: Raj Kumar Bharati | D6: NULL | E6: 828 | F6: 43980 | G6: 1 | H6: 0 | I6: 8340331478 | J6: 0 | K6: NULL | L6: NULL | M6: 0 | N6: 0 | O6: 0 | P6: 0 | Q6: 0 | R6: 0 | S6: 0 | T6: 0 | U6: 0 | V6: 0 | W6: 0 | X6: 0 | Y6: 0 | Z6: 0 | AA6: 0 | AB6: 466622309430 | AC6: 607126 | AD6: be3bd20b-9ba6-45dc-b0a2-dd3b708d7776 | AE6: 8340331478 | AF6: NULL | AG6: 1.2 | AH6: 1.2 | AI6: NULL
A7: 3394 | B7: RAJESH KUMAR | C7: RAJESH | D7: 42200 | E7: 5021 | F7: 42164 | G7: 1 | H7: 1 | I7: 8292956518 | J7: 80010127 | K7: NULL | L7: NULL | M7: 0 | N7: 0 | O7: 0 | P7: 0 | Q7: 0 | R7: 0 | S7: 0 | T7: 0 | U7: 0 | V7: 0 | W7: 0 | X7: 0 | Y7: 0 | Z7: 0 | AA7: 0 | AB7: NULL | AC7: NULL | AD7: NULL | AE7: NULL | AF7: NULL | AG7: 1.2 | AH7: 0 | AI7: NULL
A8: 7249 | B8: Enu Giri | C8: Enu Giri | D8: NULL | E8: 2130 | F8: 44590 | G8: 1 | H8: 0 | I8: 9305846126 | J8: 0 | K8: NULL | L8: NULL | M8: 0 | N8: 0 | O8: 0 | P8: 0 | Q8: 0 | R8: 0 | S8: 0 | T8: 38 | U8: 838198 | V8: 116 | W8: 568 | X8: 6623001 | Y8: 600000 | Z8: 0 | AA8: 0 | AB8: 243300213500 | AC8: 606985 | AD8: 4ef3532b-c572-4159-94bc-70f4c83a9d1d | AE8: 9305846126 | AG8: 1.2 | AH8: 1.2 | AI8: NULL
A9: 7847 | B9: Jagdish Maurya | C9: Jagdish Maurya | D9: 42903 | E9: 9809 | F9: 42919 | G9: 1 | H9: 0 | I9: 7091195160 | J9: 0 | K9: NULL | L9: NULL | M9: 0 | N9: 0 | O9: 0 | P9: 0 | Q9: 0 | R9: 0 | S9: 0 | T9: 0 | U9: 0 | V9: 0 | W9: 469 | X9: 5400328 | Y9: 0 | Z9: 0 | AA9: 0 | AB9: NULL | AC9: NULL | AD9: NULL | AE9: NULL | AF9: NULL | AG9: 1.2 | AH9: 0 | AI9: NULL
A10: 2737 | B10: Uday prakash Verma | C10: Uday prakash Verma | D10: NULL | E10: 828 | F10: 43980 | G10: 1 | H10: 1 | I10: 8318462912 | J10: 80010525 | K10: NULL | L10: NULL | M10: 0 | N10: 0 | O10: 0 | P10: 0 | Q10: 0 | R10: 0 | S10: 0 | T10: 0 | U10: 0 | V10: 0 | W10: 0 | X10: 0 | Y10: 0 | Z10: 0 | AA10: 0 | AB10: 384821858063 | AC10: 607152 | AD10: 866505047727038 | AE10: 8318462912 | AF10: NULL | AG10: 1.2 | AH10: 1.2 | AI10: NULL
A11: 2649 | B11: Mohan Lal | C11: Mohan Lal | D11: NULL | E11: 828 | F11: 43980 | G11: 1 | H11: 0 | I11: 6299342209 | J11: 0 | K11: NULL | L11: NULL | M11: 0 | N11: 0 | O11: 0 | P11: 0 | Q11: 0 | R11: 0 | S11: 0 | T11: 0 | U11: 0 | V11: 0 | W11: 0 | X11: 0 | Y11: 0 | Z11: 0 | AA11: 0 | AB11: 704567965285 | AC11: 607153 | AD11: 8ac401b8-157f-40eb-9607-d31cef822c5e | AE11: 6299342209 | AF11: NULL | AG11: 1.2 | AH11: 1.2 | AI11: NULL
A12: 4503 | B12: Suny Deol | C12: Suny Deol | D12: NULL | E12: 828 | F12: 43980 | G12: 1 | H12: 0 | I12: 7355488559 | J12: 0 | K12: NULL | L12: NULL | M12: 0 | N12: 0 | O12: 0 | P12: 0 | Q12: 0 | R12: 0 | S12: 0 | T12: 0 | U12: 0 | V12: 0 | W12: 0 | X12: 0 | Y12: 0 | Z12: 0 | AA12: 0 | AB12: 683102799585 | AC12: 607126 | AD12: 9a476d95-b458-4a9e-aa52-e6b8b0cd949d | AE12: NULL | AF12: NULL | AG12: 1.2 | AH12: 1.2 | AI12: NULL
A13: 7062 | B13: Ms Anshumala kumari | C13: Ms Anshumala kumari | D13: NULL | E13: 2130 | F13: 44590 | G13: 1 | H13: 0 | I13: 8825265628 | J13: 0 | K13: NULL | L13: NULL | M13: 0 | N13: 0 | O13: 0 | P13: 0 | Q13: 0 | R13: 0 | S13: 0 | T13: 45 | U13: 237365 | V13: 37 | W13: 535 | X13: 13341906 | Y13: 750000 | Z13: 4 | AA13: 0 | AB13: 767849859937 | AC13: 508505 | AD13: 864360049494613 | AE13: 8825265628 | AG13: 1.2 | AH13: 1.2 | AI13: NULL
A14: 8500 | B14: Ms Fatma Khatun | C14: Ms. Fatma Khatun | D14: NULL | E14: 2130 | F14: 44590 | G14: 1 | H14: 0 | I14: 9608551332 | J14: 0 | K14: NULL | L14: NULL | M14: 0 | N14: 0 | O14: 0 | P14: 0 | Q14: 0 | R14: 0 | S14: 0 | T14: 0 | U14: 355901 | V14: 50 | W14: 528 | X14: 16695119 | Y14: 818000 | Z14: 0 | AA14: 0 | AB14: 519914496870 | AC14: 607184 | AD14: 43c639af-8987-4ac0-8be2-145d13f4ba3a | AE14: 9608551332 | AG14: 1.2 | AH14: 1.2 | AI14: 0.173
A15: 4605 | B15: Bajrang Kumar | C15: s | D15: 42602 | E15: 9809 | F15: 42605 | G15: 1 | H15: 0 | I15: 8294636880 | J15: 0 | K15: NULL | L15: NULL | M15: 0 | N15: 0 | O15: 0 | P15: 0 | Q15: 0 | R15: 0 | S15: 0 | T15: 0 | U15: 0 | V15: 0 | W15: 0 | X15: 0 | Y15: 0 | Z15: 0 | AA15: 0 | AB15: NULL | AC15: NULL | AD15: NULL | AE15: NULL | AF15: NULL | AG15: 1.2 | AH15: 0 | AI15: NULL
A16: 10057 | B16: Ms Pooja | C16: Ms. Pooja | D16: 44600 | E16: 2130 | F16: 44590 | G16: 1 | H16: 0 | I16: 9174750902 | J16: 0 | K16: NULL | L16: NULL | M16: 0 | N16: 0 | O16: 0 | P16: 0 | Q16: 0 | R16: 0 | S16: 0 | T16: 0 | U16: 0 | V16: 0 | W16: 541 | X16: 13087151 | Y16: 1279462 | Z16: 2 | AA16: 0 | AB16: 455423524286 | AC16: 607094 | AD16: 868091046039053 | AE16: 9174750902 | AG16: 1.2 | AH16: 1.2 | AI16: 0
A17: 2001 | B17: Ram Prakash Yadav | C17: Ram Prakash Yadav | D17: NULL | E17: 828 | F17: 43980 | G17: 1 | H17: 1 | I17: 7320085793 | J17: 80010400 | K17: NULL | L17: NULL | M17: 0 | N17: 0 | O17: 0 | P17: 0 | Q17: 0 | R17: 0 | S17: 0 | T17: 0 | U17: 0 | V17: 0 | W17: 0 | X17: 0 | Y17: 0 | Z17: 0 | AA17: 0 | AB17: 716333600470 | AC17: 607153 | AD17: dbed01b9-3f8d-499c-b7ca-27fcc4caaa9e | AE17: 7320085793 | AF17: NULL | AG17: 1.2 | AH17: 1.2 | AI17: NULL
A18: 4009 | B18: Ruchee Kharwar | C18: Ruchee Kharwar | D18: NULL | E18: 2130 | F18: 44590 | G18: 1 | H18: 1 | I18: 8707843657 | J18: 80010428 | K18: NULL | L18: NULL | M18: 0 | N18: 0 | O18: 0 | P18: 0 | Q18: 0 | R18: 0 | S18: 0 | T18: 0 | U18: 0 | V18: 0 | W18: 0 | X18: 0 | Y18: 0 | Z18: 0 | AA18: 0 | AB18: 217777515192 | AC18: 508500 | AD18: 866081041986459 | AE18: 8707843657 | AG18: 1.2 | AH18: 1.2 | AI18: NULL
A19: 2205 | B19: Mithilesh Sharma | C19: Mithilesh Sharma | D19: NULL | E19: 828 | F19: 43980 | G19: 1 | H19: 0 | I19: 7766846886 | J19: 0 | K19: NULL | L19: NULL | M19: 0 | N19: 0 | O19: 0 | P19: 0 | Q19: 0 | R19: 0 | S19: 0 | T19: 0 | U19: 0 | V19: 0 | W19: 0 | X19: 0 | Y19: 0 | Z19: 0 | AA19: 0 | AB19: 598611053424 | AC19: 608112 | AD19: 357192109996888 | AE19: 7766846886 | AF19: NULL | AG19: 1.2 | AH19: 1.2 | AI19: NULL
A20: 1028 | B20: Akhilesh Kr Gupta | C20: aS nm | D20: 39465 | E20: 0 | F20: 39072 | G20: 1 | H20: 0 | I20: 0 | J20: 0 | K20: NULL | L20: NULL | M20: 0 | N20: 0 | O20: 0 | P20: 0 | Q20: 0 | R20: 0 | S20: 0 | T20: 0 | U20: 0 | V20: 0 | W20: 0 | X20: 0 | Y20: 0 | Z20: 0 | AA20: 0 | AB20: NULL | AC20: NULL | AD20: NULL | AE20: NULL | AF20: NULL | AG20: 1.2 | AH20: 0 | AI20: NULL
A21: 6024 | B21: Ram Parvesh | C21: htdfhb | D21: 44548 | E21: 2130 | F21: 44355 | G21: 1 | H21: 0 | I21: 9648165078 | J21: 0 | K21: NULL | L21: NULL | M21: 0 | N21: 0 | O21: 0 | P21: 0 | Q21: 0 | R21: 0 | S21: 0 | T21: 0 | U21: 59164 | V21: 37 | W21: 453 | X21: 12737340 | Y21: 257042 | Z21: 4 | AA21: 0 | AB21: NULL | AC21: NULL | AD21: e2424691-0cac-4d67-a6fe-e66d5323637b | AE21: 9517469550 | AG21: 1.2 | AH21: 1.2 | AI21: NULL
A22: 8840 | B22: Ravi Ranjan Kumar Pandey | C22: Ravi Ranjan Kumar Pandey | D22: NULL | E22: 2130 | F22: 44553 | G22: 1 | H22: 0 | I22: 7903234428 | J22: 0 | K22: NULL | L22: NULL | M22: 8462593 | N22: 422 | O22: 7146241 | P22: 0 | Q22: 2050766 | R22: 139 | S22: 0 | T22: 0 | U22: 420575 | V22: 78 | W22: 506 | X22: 19180579 | Y22: 1346500 | Z22: 3 | AA22: 0 | AB22: 599148869776 | AC22: 607027 | AD22: 869865040733178 | AE22: 7903234428 | AG22: 1.2 | AH22: 1.2 | AI22: 0.001
A23: 2641 | B23: Pramod Kumar | C23: Pramod Kumar | D23: NULL | E23: 828 | F23: 43980 | G23: 1 | H23: 0 | I23: 7985698218 | J23: 0 | K23: NULL | L23: NULL | M23: 0 | N23: 0 | O23: 0 | P23: 0 | Q23: 0 | R23: 0 | S23: 0 | T23: 0 | U23: 0 | V23: 0 | W23: 0 | X23: 0 | Y23: 0 | Z23: 0 | AA23: 0 | AB23: 991382245846 | AC23: 607085 | AD23: 353572081281504 | AE23: 7985698218 | AF23: NULL | AG23: 1.2 | AH23: 1.2 | AI23: NULL
A24: 10007 | B24: Sharda Kumari | C24: Sharda Kumari | D24: NULL | E24: 2130 | F24: 44590 | G24: 1 | H24: 0 | I24: 7667042179 | J24: 0 | K24: NULL | L24: NULL | M24: 0 | N24: 0 | O24: 0 | P24: 0 | Q24: 0 | R24: 0 | S24: 0 | T24: 0 | U24: 316878 | V24: 62 | W24: 445 | X24: 12541152 | Y24: 344364 | Z24: 12 | AA24: 0 | AB24: 384505870090 | AC24: 607027 | AD24: a46353b1-f8d1-43b2-90b1-fac9f8070f6b | AE24: 7667042179 | AG24: 1.2 | AH24: 1.2 | AI24: NULL
A25: 1408 | B25: Neeraj Narayan | C25: Sinha | D25: 43371 | E25: 9809 | F25: 43221 | G25: 1 | H25: 0 | I25: 8294636723 | J25: 0 | K25: NULL | L25: NULL | M25: 0 | N25: 0 | O25: 0 | P25: 0 | Q25: 0 | R25: 0 | S25: 0 | T25: 0 | U25: 0 | V25: 0 | W25: 0 | X25: 0 | Y25: 0 | Z25: 0 | AA25: 0 | AB25: NULL | AC25: NULL | AD25: NULL | AE25: NULL | AF25: NULL | AG25: 1.2 | AH25: 0 | AI25: NULL
A26: 1887 | B26: Punam Devi | C26: iwwuedqekjh | D26: 42255 | E26: 2130 | F26: 42164 | G26: 1 | H26: 0 | I26: 7763811414 | J26: 0 | K26: NULL | L26: NULL | M26: 0 | N26: 0 | O26: 0 | P26: 0 | Q26: 0 | R26: 0 | S26: 0 | T26: 0 | U26: 0 | V26: 0 | W26: 0 | X26: 0 | Y26: 0 | Z26: 0 | AA26: 0 | AB26: NULL | AC26: NULL | AD26: NULL | AE26: NULL | AF26: NULL | AG26: 1.2 | AH26: 0 | AI26: NULL
A27: 1669 | B27: Yasmin Bano | C27: yyyyy | D27: NULL | E27: 2130 | F27: 44590 | G27: 1 | H27: 1 | I27: 6393605439 | J27: 80010462 | K27: NULL | L27: NULL | M27: 0 | N27: 0 | O27: 0 | P27: 0 | Q27: 0 | R27: 0 | S27: 0 | T27: 0 | U27: 0 | V27: 0 | W27: 0 | X27: 0 | Y27: 0 | Z27: 0 | AA27: 0 | AB27: 988207909193 | AC27: 607396 | AD27: 8b512e2f-ab66-4f15-972f-91d25bee4c20 | AE27: 6393605439 | AG27: 1.2 | AH27: 1.2 | AI27: NULL
A28: 16767 | B28: Ms. Suman Kumari | C28: Ms. Suman Kumari | D28: 43951 | E28: 9809 | F28: 43967 | G28: 1 | H28: 0 | I28: 0 | J28: 0 | K28: NULL | L28: NULL | M28: 0 | N28: 0 | O28: 0 | P28: 0 | Q28: 0 | R28: 0 | S28: 0 | T28: 0 | U28: 0 | V28: 0 | W28: NULL | X28: NULL | Y28: NULL | Z28: NULL | AA28: 0 | AB28: NULL | AC28: NULL | AD28: NULL | AE28: NULL | AF28: NULL | AG28: 1.2 | AH28: 0 | AI28: NULL
A29: 1662 | B29: Satyendra Prasad | C29: a | D29: NULL | E29: 828 | F29: 43980 | G29: 1 | H29: 0 | I29: 8840978213 | J29: 0 | K29: NULL | L29: NULL | M29: 0 | N29: 0 | O29: 0 | P29: 0 | Q29: 0 | R29: 0 | S29: 0 | T29: 0 | U29: 0 | V29: 0 | W29: 0 | X29: 0 | Y29: 0 | Z29: 0 | AA29: 0 | AB29: 320051027609 | AC29: 607153 | AD29: 865241033734397 | AE29: 8840978213 | AF29: NULL | AG29: 1.2 | AH29: 1.2 | AI29: NULL
A30: 5521 | B30: Mr Anjan Kumar Singh | C30: Mr. Anjan Kumar Singh | D30: NULL | E30: 9809 | F30: 44427 | G30: 1 | H30: 0 | I30: 8340345495 | J30: 0 | K30: NULL | L30: NULL | M30: 0 | N30: 0 | O30: 0 | P30: 0 | Q30: 0 | R30: 0 | S30: 0 | T30: 0 | U30: 0 | V30: 0 | W30: 0 | X30: 0 | Y30: 0 | Z30: 0 | AA30: 0 | AB30: 565948059074 | AC30: ORIENTAL BANK OF COMMERCE | AD30: 865868045143272 | AE30: 8340345495 | AG30: 1.2 | AH30: 1.2 | AI30: NULL
A31: 2011 | B31: Manoj Kumar Madhesiya | C31: Manoj Kumar Madhesiya | D31: NULL | E31: 828 | F31: 43980 | G31: 1 | H31: 1 | I31: 9140050911 | J31: 80010391 | K31: NULL | L31: NULL | M31: 0 | N31: 0 | O31: 0 | P31: 0 | Q31: 0 | R31: 0 | S31: 0 | T31: 0 | U31: 0 | V31: 0 | W31: 0 | X31: 0 | Y31: 0 | Z31: 0 | AA31: 0 | AB31: 695950908000 | AC31: 607094 | AD31: 865158032739112 | AE31: 9140050911 | AF31: NULL | AG31: 1.2 | AH31: 1.2 | AI31: NULL
A32: 9650 | B32: Mr. Sandeep Kumar Jaiswal | C32: Mr. Sandeep Kumar Jaiswal | D32: NULL | E32: 9809 | F32: 44428 | G32: 1 | H32: 0 | I32: 0 | J32: 0 | K32: NULL | L32: NULL | M32: 0 | N32: 0 | O32: 0 | P32: 0 | Q32: 0 | R32: 0 | S32: 0 | T32: 0 | U32: 580065 | V32: 89 | W32: 463 | X32: 12630279 | Y32: 719000 | Z32: 8 | AA32: 0 | AB32: NULL | AC32: NULL | AD32: 9592f8b8-aff3-42ff-9508-fda60afafe7c | AE32: 8808511361 | AG32: 1.2 | AH32: 1.2 | AI32: NULL
A33: 4676 | B33: Sunil Kumar Singh | C33: Sunil Kumar Singh | D33: 44422 | E33: 9809 | F33: 43061 | G33: 1 | H33: 0 | I33: 8825113861 | J33: 0 | K33: NULL | L33: NULL | M33: 0 | N33: 0 | O33: 0 | P33: 0 | Q33: 0 | R33: 0 | S33: 0 | T33: 0 | U33: 0 | V33: 0 | W33: 0 | X33: 0 | Y33: 0 | Z33: 0 | AA33: 0 | AB33: 272107902995 | AC33: 607094 | AD33: 862926047687614 | AE33: 8825113861 | AF33: NULL | AG33: 1.2 | AH33: 1.2 | AI33: NULL
A34: 3718 | B34: DEEPAK KUMAR | C34: A | D34: 42371 | E34: 9809 | F34: 42164 | G34: 1 | H34: 0 | I34: 8292955594 | J34: 0 | K34: NULL | L34: NULL | M34: 0 | N34: 0 | O34: 0 | P34: 0 | Q34: 0 | R34: 0 | S34: 0 | T34: 0 | U34: 0 | V34: 0 | W34: 0 | X34: 0 | Y34: 0 | Z34: 0 | AA34: 0 | AB34: NULL | AC34: NULL | AD34: NULL | AE34: NULL | AF34: NULL | AG34: 1.2 | AH34: 0 | AI34: NULL
A35: 3022 | B35: Mohan Ray | C35: Mohan Ray | D35: NULL | E35: 828 | F35: 43980 | G35: 1 | H35: 0 | I35: 9304375067 | J35: 0 | K35: NULL | L35: NULL | M35: 0 | N35: 0 | O35: 0 | P35: 0 | Q35: 0 | R35: 0 | S35: 0 | T35: 0 | U35: 0 | V35: 0 | W35: 0 | X35: 0 | Y35: 0 | Z35: 0 | AA35: 0 | AB35: 287539673563 | AC35: 607085 | AD35: 5ed03f3f-3efd-4a3f-a050-cbd8897dadb8 | AE35: 9304375067 | AF35: NULL | AG35: 1.2 | AH35: 1.2 | AI35: NULL
A36: 11621 | B36: Mr Sachindra | C36: Mr. Sachindra | D36: NULL | E36: 2130 | F36: 44590 | G36: 1 | H36: 0 | I36: 8318784926 | J36: 0 | K36: NULL | L36: NULL | M36: 0 | N36: 0 | O36: 0 | P36: 0 | Q36: 0 | R36: 0 | S36: 0 | T36: 0 | U36: 0 | V36: 0 | W36: 517 | X36: 15908493 | Y36: 500000 | Z36: 20 | AA36: 0 | AB36: 740062156441 | AC36: 608112 | AD36: 861001045904212 | AE36: 8318784926 | AG36: 1.2 | AH36: 1.2 | AI36: 0

Sheet Pendency
A1: BranchName | B1: BranchID | C1: CHid | D1: CHName | E1: NoOfClientsdue | F1: LoanamtDue | G1: NoOfClientsDisbursed | H1: LoanamtDisbursed | I1: NoOfArrear | J1: ArrearAmt | K1: PerALC | L1: PerAmt | M1: DayCloseRemark
A2: ='Pendency (2)'!A2 -> Damodarpur | B2: ='Pendency (2)'!B2 -> 21:01 | C2: ='Pendency (2)'!C2 -> 0729 | D2: ='Pendency (2)'!D2 -> Mr Kamlesh Kumar Singh | E2: ='Pendency (2)'!E2 -> 6 | F2: ='Pendency (2)'!F2 -> 280000 | G2: ='Pendency (2)'!G2 -> 5 | H2: ='Pendency (2)'!H2 -> 250000 | ... M2: ='Pendency (2)'!M2 -> DayClose
A3: ='Pendency (2)'!A3 -> Sakari Saraiya | B3: ='Pendency (2)'!B3 -> 21:16 | C3: ='Pendency (2)'!C3 -> 0729 | D3: ='Pendency (2)'!D3 -> Mr Kamlesh Kumar Singh | E3: ='Pendency (2)'!E3 -> 4 | F3: ='Pendency (2)'!F3 -> 120000 | G3: ='Pendency (2)'!G3 -> 4 | H3: ='Pendency (2)'!H3 -> 120000 | ... M3: ='Pendency (2)'!M3 -> DayClosePending
A4: ='Pendency (2)'!A4 -> Karja | B4: ='Pendency (2)'!B4 -> 21:02 | C4: ='Pendency (2)'!C4 -> 0729 | D4: ='Pendency (2)'!D4 -> Mr Kamlesh Kumar Singh | E4: ='Pendency (2)'!E4 -> 24 | F4: ='Pendency (2)'!F4 -> 1280000 | G4: ='Pendency (2)'!G4 -> 15 | H4: ='Pendency (2)'!H4 -> 810000 | ... M4: ='Pendency (2)'!M4 -> DayClosePending
A5: ='Pendency (2)'!A5 -> Kurhani | B5: ='Pendency (2)'!B5 -> 21:11 | C5: ='Pendency (2)'!C5 -> 0729 | D5: ='Pendency (2)'!D5 -> Mr Kamlesh Kumar Singh | E5: ='Pendency (2)'!E5 -> 21 | F5: ='Pendency (2)'!F5 -> 986000 | G5: ='Pendency (2)'!G5 -> 4 | H5: ='Pendency (2)'!H5 -> 140000 | ... M5: ='Pendency (2)'!M5 -> DayClosePending
A6: ='Pendency (2)'!A6 -> Goraul | B6: ='Pendency (2)'!B6 -> 21:18 | C6: ='Pendency (2)'!C6 -> 0729 | D6: ='Pendency (2)'!D6 -> Mr Kamlesh Kumar Singh | E6: ='Pendency (2)'!E6 -> 25 | F6: ='Pendency (2)'!F6 -> 1335000 | G6: ='Pendency (2)'!G6 -> 15 | H6: ='Pendency (2)'!H6 -> 880000 | ... M6: ='Pendency (2)'!M6 -> DayClosePending
A7: ='Pendency (2)'!A7 -> Belsar | B7: ='Pendency (2)'!B7 -> 21:21 | C7: ='Pendency (2)'!C7 -> 0729 | D7: ='Pendency (2)'!D7 -> Mr Kamlesh Kumar Singh | E7: ='Pendency (2)'!E7 -> 15 | F7: ='Pendency (2)'!F7 -> 980000 | G7: ='Pendency (2)'!G7 -> 6 | H7: ='Pendency (2)'!H7 -> 520000 | ... M7: ='Pendency (2)'!M7 -> DayClosePending
E8: =SUM(E2:E7) -> 95 | F8: =SUM(F2:F7) -> 4981000 | G8: =SUM(G2:G7) -> 49 | H8: =SUM(H2:H7) -> 2720000 | I8: =SUM(I2:I7) -> 38 | J8: =SUM(J2:J7) -> 4395 | K8: =+G8/E8*100 -> 51.578947 | L8: =+H8/F8*100 -> 54.607509
A9: ='Pendency (2)'!A8 -> Murual | B9: ='Pendency (2)'!B8 -> 21:07 | C9: ='Pendency (2)'!C8 -> 4299 | D9: ='Pendency (2)'!D8 -> Mr Dharmatma Kumar Manjhi | E9: ='Pendency (2)'!E8 -> 16 | F9: ='Pendency (2)'!F8 -> 800000 | G9: ='Pendency (2)'!G8 -> 8 | H9: ='Pendency (2)'!H8 -> 430000 | ... M9: ='Pendency (2)'!M8 -> DayClosePending
A10: ='Pendency (2)'!A9 -> Hayaghat | B10: ='Pendency (2)'!B9 -> 21:27 | C10: ='Pendency (2)'!C9 -> 4299 | D10: ='Pendency (2)'!D9 -> Mr Dharmatma Kumar Manjhi | E10: ='Pendency (2)'!E9 -> 12 | F10: ='Pendency (2)'!F9 -> 670000 | G10: ='Pendency (2)'!G9 -> 7 | H10: ='Pendency (2)'!H9 -> 460000 | ... M10: ='Pendency (2)'!M9 -> DayClosePending
A11: ='Pendency (2)'!A10 -> Mahanth Maniyari | B11: ='Pendency (2)'!B10 -> 21:17 | C11: ='Pendency (2)'!C10 -> 4299 | D11: ='Pendency (2)'!D10 -> Mr Dharmatma Kumar Manjhi | E11: ='Pendency (2)'!E10 -> 16 | F11: ='Pendency (2)'!F10 -> 680000 | G11: ='Pendency (2)'!G10 -> 7 | H11: ='Pendency (2)'!H10 -> 350000 | ... M11: ='Pendency (2)'!M10 -> DayClosePending
A12: ='Pendency (2)'!A11 -> Pear | B12: ='Pendency (2)'!B11 -> 21:09 | C12: ='Pendency (2)'!C11 -> 4299 | D12: ='Pendency (2)'!D11 -> Mr Dharmatma Kumar Manjhi | E12: ='Pendency (2)'!E11 -> 10 | F12: ='Pendency (2)'!F11 -> 590000 | G12: ='Pendency (2)'!G11 -> 5 | H12: ='Pendency (2)'!H11 -> 310000 | ... M12: ='Pendency (2)'!M11 -> DayClosePending
A13: ='Pendency (2)'!A12 -> Hanuman Nagar | B13: ='Pendency (2)'!B12 -> 21:25 | C13: ='Pendency (2)'!C12 -> 4299 | D13: ='Pendency (2)'!D12 -> Mr Dharmatma Kumar Manjhi | E13: ='Pendency (2)'!E12 -> 18 | F13: ='Pendency (2)'!F12 -> 930000 | G13: ='Pendency (2)'!G12 -> 9 | H13: ='Pendency (2)'!H12 -> 460000 | ... M13: ='Pendency (2)'!M12 -> DayClosePending
A14: ='Pendency (2)'!A13 -> Patepur | B14: ='Pendency (2)'!B13 -> 21:20 | C14: ='Pendency (2)'!C13 -> 4299 | D14: ='Pendency (2)'!D13 -> Mr Dharmatma Kumar Manjhi | E14: ='Pendency (2)'!E13 -> 17 | F14: ='Pendency (2)'!F13 -> 1060000 | G14: ='Pendency (2)'!G13 -> 10 | H14: ='Pendency (2)'!H13 -> 650000 | ... M14: ='Pendency (2)'!M13 -> DayClosePending
E15: =SUM(E9:E14) -> 89 | F15: =SUM(F9:F14) -> 4730000 | G15: =SUM(G9:G14) -> 46 | H15: =SUM(H9:H14) -> 2660000 | I15: =SUM(I9:I14) -> 1 | J15: =SUM(J9:J14) -> 20 | K15: =+G15/E15*100 -> 51.685393 | L15: =+H15/F15*100 -> 56.236786
A16: ='Pendency (2)'!A14 -> Jhapaha | B16: ='Pendency (2)'!B14 -> 21:19 | C16: ='Pendency (2)'!C14 -> 4724 | D16: ='Pendency (2)'!D14 -> Mr Subhash Chandra Gupta | E16: ='Pendency (2)'!E14 -> 9 | F16: ='Pendency (2)'!F14 -> 610000 | G16: ='Pendency (2)'!G14 -> 3 | H16: ='Pendency (2)'!H14 -> 170000 | ... M16: ='Pendency (2)'!M14 -> DayClosePending
A17: ='Pendency (2)'!A15 -> Phulwariya | B17: ='Pendency (2)'!B15 -> 21:13 | C17: ='Pendency (2)'!C15 -> 4724 | D17: ='Pendency (2)'!D15 -> Mr Subhash Chandra Gupta | E17: ='Pendency (2)'!E15 -> 10 | F17: ='Pendency (2)'!F15 -> 680000 | G17: ='Pendency (2)'!G15 -> 5 | H17: ='Pendency (2)'!H15 -> 300000 | ... M17: ='Pendency (2)'!M15 -> DayClosePending
A18: ='Pendency (2)'!A16 -> Dewariya | B18: ='Pendency (2)'!B16 -> 21:14 | C18: ='Pendency (2)'!C16 -> 4724 | D18: ='Pendency (2)'!D16 -> Mr Subhash Chandra Gupta | E18: ='Pendency (2)'!E16 -> 22 | F18: ='Pendency (2)'!F16 -> 1210000 | G18: ='Pendency (2)'!G16 -> 13 | H18: ='Pendency (2)'!H16 -> 690000 | ... M18: ='Pendency (2)'!M16 -> DayClosePending
A19: ='Pendency (2)'!A17 -> Runnisaidpur | B19: ='Pendency (2)'!B17 -> 21:22 | C19: ='Pendency (2)'!C17 -> 4724 | D19: ='Pendency (2)'!D17 -> Mr Subhash Chandra Gupta | E19: ='Pendency (2)'!E17 -> 25 | F19: ='Pendency (2)'!F17 -> 1680000 | G19: ='Pendency (2)'!G17 -> 21 | H19: ='Pendency (2)'!H17 -> 1450000 | ... M19: ='Pendency (2)'!M17 -> DayClosePending
A20: ='Pendency (2)'!A18 -> Motipur | B20: ='Pendency (2)'!B18 -> 21:06 | C20: ='Pendency (2)'!C18 -> 4724 | D20: ='Pendency (2)'!D18 -> Mr Subhash Chandra Gupta | E20: ='Pendency (2)'!E18 -> 15 | F20: ='Pendency (2)'!F18 -> 880000 | G20: ='Pendency (2)'!G18 -> 11 | H20: ='Pendency (2)'!H18 -> 630000 | ... M20: ='Pendency (2)'!M18 -> DayClosePending
A21: ='Pendency (2)'!A19 -> Minapur | B21: ='Pendency (2)'!B19 -> 21:10 | C21: ='Pendency (2)'!C19 -> 4724 | D21: ='Pendency (2)'!D19 -> Mr Subhash Chandra Gupta | E21: ='Pendency (2)'!E19 -> 6 | F21: ='Pendency (2)'!F19 -> 350000 | G21: ='Pendency (2)'!G19 -> 5 | H21: ='Pendency (2)'!H19 -> 320000 | ... M21: ='Pendency (2)'!M19 -> DayClosePending
E22: =SUM(E16:E21) -> 87 | F22: =SUM(F16:F21) -> 5410000 | G22: =SUM(G16:G21) -> 58 | H22: =SUM(H16:H21) -> 3560000 | I22: =SUM(I16:I21) -> 4 | J22: =SUM(J16:J21) -> 2854 | K22: =+G22/E22*100 -> 66.666667 | L22: =+H22/F22*100 -> 65.804067
A23: ='Pendency (2)'!A20 -> Baruari | B23: ='Pendency (2)'!B20 -> 21:23 | C23: ='Pendency (2)'!C20 -> 5999 | D23: ='Pendency (2)'!D20 -> Sunil kumar Pandey | E23: ='Pendency (2)'!E20 -> 23 | F23: ='Pendency (2)'!F20 -> 1115000 | G23: ='Pendency (2)'!G20 -> 12 | H23: ='Pendency (2)'!H20 -> 790000 | ... M23: ='Pendency (2)'!M20 -> DayClosePending
A24: ='Pendency (2)'!A21 -> Sarfuddinpur | B24: ='Pendency (2)'!B21 -> 21:08 | C24: ='Pendency (2)'!C21 -> 5999 | D24: ='Pendency (2)'!D21 -> Sunil kumar Pandey | E24: ='Pendency (2)'!E21 -> 13 | F24: ='Pendency (2)'!F21 -> 850000 | G24: ='Pendency (2)'!G21 -> 5 | H24: ='Pendency (2)'!H21 -> 510000 | ... M24: ='Pendency (2)'!M21 -> DayClosePending
A25: ='Pendency (2)'!A22 -> Bhusara | B25: ='Pendency (2)'!B22 -> 21:15 | C25: ='Pendency (2)'!C22 -> 5999 | D25: ='Pendency (2)'!D22 -> Sunil kumar Pandey | E25: ='Pendency (2)'!E22 -> 14 | F25: ='Pendency (2)'!F22 -> 530000 | G25: ='Pendency (2)'!G22 -> 3 | H25: ='Pendency (2)'!H22 -> 90000 | ... M25: ='Pendency (2)'!M22 -> DayClosePending
A26: ='Pendency (2)'!A23 -> Jalle | B26: ='Pendency (2)'!B23 -> 21:28 | C26: ='Pendency (2)'!C23 -> 5999 | D26: ='Pendency (2)'!D23 -> Sunil kumar Pandey | E26: ='Pendency (2)'!E23 -> 11 | F26: ='Pendency (2)'!F23 -> 470000 | G26: ='Pendency (2)'!G23 -> 7 | H26: ='Pendency (2)'!H23 -> 355000 | ... M26: ='Pendency (2)'!M23 -> DayClosePending
A27: ='Pendency (2)'!A24 -> Bochahan | B27: ='Pendency (2)'!B24 -> 21:12 | C27: ='Pendency (2)'!C24 -> 5999 | D27: ='Pendency (2)'!D24 -> Sunil kumar Pandey | E27: ='Pendency (2)'!E24 -> 8 | F27: ='Pendency (2)'!F24 -> 470000 | G27: ='Pendency (2)'!G24 -> 5 | H27: ='Pendency (2)'!H24 -> 280000 | ... M27: ='Pendency (2)'!M24 -> DayClosePending
A28: ='Pendency (2)'!A25 -> Bharwada | B28: ='Pendency (2)'!B25 -> 21:26 | C28: ='Pendency (2)'!C25 -> 5999 | D28: ='Pendency (2)'!D25 -> Sunil kumar Pandey | E28: ='Pendency (2)'!E25 -> 14 | F28: ='Pendency (2)'!F25 -> 730000 | G28: ='Pendency (2)'!G25 -> 6 | H28: ='Pendency (2)'!H25 -> 380000 | ... M28: ='Pendency (2)'!M25 -> DayClosePending
E29: =SUM(E23:E28) -> 83 | F29: =SUM(F23:F28) -> 4165000 | G29: =SUM(G23:G28) -> 38 | H29: =SUM(H23:H28) -> 2405000 | I29: =SUM(I23:I28) -> 6 | J29: =SUM(J23:J28) -> 1785 | K29: =+G29/E29*100 -> 45.783133 | L29: =+H29/F29*100 -> 57.743097
D30: Total | E30: =E8+E15+E22+E29 -> 354 | F30: =F8+F15+F22+F29 -> 19286000 | G30: =G8+G15+G22+G29 -> 191 | H30: =H8+H15+H22+H29 -> 11345000 | I30: =I8+I15+I22+I29 -> 49 | J30: =J8+J15+J22+J29 -> 9054 | K30: =+G30/E30*100 -> 53.954802 | L30: =+H30/F30*100 -> 58.825054

Sheet Pendency (2)
A1: BranchName | B1: BranchID | C1: CHid | D1: CHName | E1: NoOfClientsdue | F1: LoanamtDue | G1: NoOfClientsDisbursed | H1: LoanamtDisbursed | I1: NoOfArrear | J1: ArrearAmt | K1: PerALC | L1: PerAmt | M1: DayCloseRemark
A2: Damodarpur | B2: 21:01 | C2: 0729 | D2: Mr Kamlesh Kumar Singh | E2: 6 | F2: 280000 | G2: 5 | H2: 250000 | I2: 2 | J2: 1038 | K2: 83.33 | L2: 89.29 | M2: DayClose
A3: Sakari Saraiya | B3: 21:16 | C3: 0729 | D3: Mr Kamlesh Kumar Singh | E3: 4 | F3: 120000 | G3: 4 | H3: 120000 | I3: 7 | J3: 621 | K3: 100 | L3: 100 | M3: DayClosePending
A4: Karja | B4: 21:02 | C4: 0729 | D4: Mr Kamlesh Kumar Singh | E4: 24 | F4: 1280000 | G4: 15 | H4: 810000 | I4: 14 | J4: 1096 | K4: 62.5 | L4: 63.28 | M4: DayClosePending
A5: Kurhani | B5: 21:11 | C5: 0729 | D5: Mr Kamlesh Kumar Singh | E5: 21 | F5: 986000 | G5: 4 | H5: 140000 | I5: 2 | J5: 114 | K5: 19.05 | L5: 14.2 | M5: DayClosePending
A6: Goraul | B6: 21:18 | C6: 0729 | D6: Mr Kamlesh Kumar Singh | E6: 25 | F6: 1335000 | G6: 15 | H6: 880000 | I6: 2 | J6: 584 | K6: 60 | L6: 65.92 | M6: DayClosePending
A7: Belsar | B7: 21:21 | C7: 0729 | D7: Mr Kamlesh Kumar Singh | E7: 15 | F7: 980000 | G7: 6 | H7: 520000 | I7: 11 | J7: 942 | K7: 40 | L7: 53.06 | M7: DayClosePending
A8: Murual | B8: 21:07 | C8: 4299 | D8: Mr Dharmatma Kumar Manjhi | E8: 16 | F8: 800000 | G8: 8 | H8: 430000 | I8: 0 | J8: 0 | K8: 50 | L8: 53.75 | M8: DayClosePending
A9: Hayaghat | B9: 21:27 | C9: 4299 | D9: Mr Dharmatma Kumar Manjhi | E9: 12 | F9: 670000 | G9: 7 | H9: 460000 | I9: 0 | J9: 0 | K9: 58.33 | L9: 68.66 | M9: DayClosePending
A10: Mahanth Maniyari | B10: 21:17 | C10: 4299 | D10: Mr Dharmatma Kumar Manjhi | E10: 16 | F10: 680000 | G10: 7 | H10: 350000 | I10: 0 | J10: 0 | K10: 43.75 | L10: 51.47 | M10: DayClosePending
A11: Pear | B11: 21:09 | C11: 4299 | D11: Mr Dharmatma Kumar Manjhi | E11: 10 | F11: 590000 | G11: 5 | H11: 310000 | I11: 0 | J11: 0 | K11: 50 | L11: 52.54 | M11: DayClosePending
A12: Hanuman Nagar | B12: 21:25 | C12: 4299 | D12: Mr Dharmatma Kumar Manjhi | E12: 18 | F12: 930000 | G12: 9 | H12: 460000 | I12: 0 | J12: 0 | K12: 50 | L12: 49.46 | M12: DayClosePending
A13: Patepur | B13: 21:20 | C13: 4299 | D13: Mr Dharmatma Kumar Manjhi | E13: 17 | F13: 1060000 | G13: 10 | H13: 650000 | I13: 1 | J13: 20 | K13: 58.82 | L13: 61.32 | M13: DayClosePending
A14: Jhapaha | B14: 21:19 | C14: 4724 | D14: Mr Subhash Chandra Gupta | E14: 9 | F14: 610000 | G14: 3 | H14: 170000 | I14: 2 | J14: 2000 | K14: 33.33 | L14: 27.87 | M14: DayClosePending
A15: Phulwariya | B15: 21:13 | C15: 4724 | D15: Mr Subhash Chandra Gupta | E15: 10 | F15: 680000 | G15: 5 | H15: 300000 | I15: 0 | J15: 0 | K15: 50 | L15: 44.12 | M15: DayClosePending
A16: Dewariya | B16: 21:14 | C16: 4724 | D16: Mr Subhash Chandra Gupta | E16: 22 | F16: 1210000 | G16: 13 | H16: 690000 | I16: 0 | J16: 0 | K16: 59.09 | L16: 57.02 | M16: DayClosePending
A17: Runnisaidpur | B17: 21:22 | C17: 4724 | D17: Mr Subhash Chandra Gupta | E17: 25 | F17: 1680000 | G17: 21 | H17: 1450000 | I17: 1 | J17: 695 | K17: 84 | L17: 86.31 | M17: DayClosePending
A18: Motipur | B18: 21:06 | C18: 4724 | D18: Mr Subhash Chandra Gupta | E18: 15 | F18: 880000 | G18: 11 | H18: 630000 | I18: 0 | J18: 0 | K18: 73.33 | L18: 71.59 | M18: DayClosePending
A19: Minapur | B19: 21:10 | C19: 4724 | D19: Mr Subhash Chandra Gupta | E19: 6 | F19: 350000 | G19: 5 | H19: 320000 | I19: 1 | J19: 159 | K19: 83.33 | L19: 91.43 | M19: DayClosePending
A20: Baruari | B20: 21:23 | C20: 5999 | D20: Sunil kumar Pandey | E20: 23 | F20: 1115000 | G20: 12 | H20: 790000 | I20: 0 | J20: 0 | K20: 52.17 | L20: 70.85 | M20: DayClosePending
A21: Sarfuddinpur | B21: 21:08 | C21: 5999 | D21: Sunil kumar Pandey | E21: 13 | F21: 850000 | G21: 5 | H21: 510000 | I21: 4 | J21: 177 | K21: 38.46 | L21: 60 | M21: DayClosePending
... A25: Bharwada | B25: 21:26 | C25: 5999 | D25: Sunil kumar Pandey | E25: 14 | F25: 730000 | G25: 6 | H25: 380000 | I25: 0 | J25: 0 | K25: 42.86 | L25: 52.05 | M25: DayClosePending
D26: Total | E26: =SUM(E2:E25) -> 354 | F26: =SUM(F2:F25) -> 19286000 | G26: =SUM(G2:G25) -> 191 | H26: =SUM(H2:H25) -> 11345000 | I26: =SUM(I2:I25) -> 49 | J26: =SUM(J2:J25) -> 9054 | K26: =+G26/E26*100 -> 53.954802 | L26: =+H26/F26*100 -> 58.825054

Sheet Hospi Cash
A1: Hospi Cash (Health Insurance) Detail Till Now | W1: Muzaffarpur Hospicash Detail
A2: zone | B2: Regionname | C2: ALC | D2: AmountClient | E2: ALC | F2: AmountSpouse | W2: Branchid | X2: Branchname | Y2: ALC | Z2: AmountSpouse | AA2: Branchid | AB2: Branchname | AC2: ALC | AD2: AmountSpouse
A3: HOT-North East Zone | B3: EAST CHAMPARAN | C3: 704 | D3: 111450 | E3: 589 | F3: 93300 | W3: 0.87569444 | X3: DAMODARPUR | Y3: 96 | Z3: 14400 | AA3: 0.87569444 | AB3: DAMODARPUR | AC3: 85 | AD3: 12750
A4: HOT-North East Zone | B4: SARAN | C4: 734 | D4: 112800 | E4: 347 | F4: 53250 | W4: 0.87638889 | X4: KARJA | Y4: 36 | Z4: 5400 | AA4: 0.87638889 | AB4: KARJA | AC4: 25 | AD4: 3750
A5: HOT-North East Zone | B5: SIWAN | C5: 2813 | D5: 446850 | E5: 1870 | F5: 291450 | W5: 0.87916667 | X5: MOTIPUR | Y5: 115 | Z5: 18300 | AA5: 0.87916667 | AB5: MOTIPUR | AC5: 102 | AD5: 15450
B6: Total | C6: =SUM(C3:C5) -> 4251 | D6: =SUM(D3:D5) -> 671100 | E6: =SUM(E3:E5) -> 2806 | F6: =SUM(F3:F5) -> 438000 | W6: 0.87986111 | X6: MURUAL | Y6: 192 | Z6: 28800 | AA6: 0.87986111 | AB6: MURUAL | AC6: 178 | AD6: 26700
A7: zone | B7: Regionname | C7: ALC | D7: AmountClient | E7: ALC | F7: AmountSpouse | W7: 0.88055556 | X7: SARFUDDINPUR | Y7: 182 | Z7: 27300 | AA7: 0.88055556 | AB7: SARFUDDINPUR | AC7: 188 | AD7: 30150
A8: HOT-North East Zone | B8: MUZAFFARPUR | C8: 1723 | D8: 262500 | E8: 1248 | F8: 189600 | W8: 0.88125 | X8: PEAR | Y8: 86 | Z8: 12900 | AA8: 0.88125 | AB8: PEAR | AC8: 78 | AD8: 11700
A9: HOT-NORTH EAST ZONE | B9: SAMASTIPUR | C9: 1755 | D9: 267900 | E9: 1552 | F9: 236400 | W9: 0.88194444 | X9: MINAPUR | Y9: 6 | Z9: 900 | AA9: 0.88194444 | AB9: MINAPUR | AC9: 7 | AD9: 1050
A10: HOT-North East Zone | B10: SitamarhiDarbhanga | C10: 736 | D10: 113850 | E10: 622 | F10: 95250 | W10: 0.88263889 | X10: KURHANI | Y10: 22 | Z10: 3300 | AA10: 0.88263889 | AB10: KURHANI | AC10: 21 | AD10: 3150
B11: Total | C11: =SUM(C8:C10) -> 4214 | D11: =SUM(D8:D10) -> 644250 | E11: =SUM(E8:E10) -> 3422 | F11: =SUM(F8:F10) -> 521250 | W11: 0.88333333 | X11: BOCHAHAN | Y11: 79 | Z11: 11850 | AA11: 0.88333333 | AB11: BOCHAHAN | AC11: 218 | AD11: 32700
B12: G Total | C12: =+C6+C11 -> 8465 | D12: =+D6+D11 -> 1315350 | E12: =+E6+E11 -> 6228 | F12: =+F6+F11 -> 959250 | W12: 0.88402778 | X12: PHULWARIYA | Y12: 37 | Z12: 5850 | AA12: 0.88402778 | AB12: PHULWARIYA | AC12: 9 | AD12: 1500
W13: 0.88611111 | X13: SAKARI SARAIYA | Y13: 3 | Z13: 450 | AA13: 0.88680556 | AB13: MAHANTH MANIYARI | AC13: 158 | AD13: 23700
A14: HOT-North East Zone ACTIAM Loan Utilization Report | W14: 0.88680556 | X14: MAHANTH MANIYARI | Y14: 154 | Z14: 23100 | AA14: 0.88819444 | AB14: JHAPAHA | AC14: 8 | AD14: 1200
A15: Zone | B15: Regionname | C15: ACTIAMLUCDetail | W15: 0.8875 | X15: GORAUL | Y15: 2 | Z15: 300 | AA15: 0.88888889 | AB15: PATEPUR | AC15: 3 | AD15: 450
A16: HOT-North East Zone | B16: SITAMARHI&DARBHANGA | C16: 0 | W16: 0.88819444 | X16: JHAPAHA | Y16: 172 | Z16: 25950 | AA16: 0.88958333 | AB16: BELSAR | AC16: 3 | AD16: 450
A17: HOT-North East Zone | B17: MUZAFFARPUR | C17: 0 | W17: 0.88888889 | X17: PATEPUR | Y17: 3 | Z17: 450 | AA17: 0.89097222 | AB17: BARUARI | AC17: 8 | AD17: 1200
A18: HOT-North East Zone | B18: SIWAN | C18: 1042 | W18: 0.88958333 | X18: BELSAR | Y18: 3 | Z18: 450 | AA18: 0.89236111 | AB18: HANUMAN NAGAR | AC18: 5 | AD18: 750
A19: HOT-North East Zone | B19: SARAN | C19: 743 | W19: 0.89027778 | X19: RUNNISAIDPUR | Y19: 28 | Z19: 4200 | AA19: 0.89305556 | AB19: BHARWADA | AC19: 33 | AD19: 4950
A20: HOT-North East Zone | B20: EAST CHAMPARAN | C20: 1241 | W20: 0.89097222 | X20: BARUARI | Y20: 9 | Z20: 1350 | AA20: 0.89375 | AB20: HAYAGHAT | AC20: 68 | AD20: 10350
B21: Total | C21: =SUM(C16:C20) -> 3026 | W21: 0.89236111 | X21: HANUMAN NAGAR | Y21: 261 | Z21: 39300 | AA21: 0.89444444 | AB21: JALLE | AC21: 16 | AD21: 2400
X22: Total | Y22: =SUM(Y3:Y21) -> 1486 | Z22: =SUM(Z3:Z21) -> 224550
A23: Zone M Insure Collection Detail | O23: Handle By
C24: Total From 01.10.2021 To Till Date | I24: Total As on Dated 24.01.2022
C25: By Cashpor | E25: By Self | G25: Grand Total Upto Till Date | I25: By Cashpor | K25: By Self | M25: Grand Total As On 24.01.2022
A26: Zone | B26: Regionname | C26: Total NO_ALC | D26: Amount | E26: Total NO_ALC | F26: Amount | G26: Total NO_ALC | H26: Amount | I26: Total NO_ALC | J26: Amount | K26: Total NO_ALC | L26: Amount | M26: Total NO_ALC | N26: Amount
A27: HOT-North East Zone | B27: MUZAFFARPUR | C27: 1153 | D27: 75650 | E27: 9665 | F27: 970000 | G27: =+C27+E27 -> 10818 | H27: =+D27+F27 -> 1045650 | I27: 0 | J27: 0 | K27: 196 | L27: 19600 | M27: =+I27+K27 -> 196 | N27: =+J27+L27 -> 19600 | O27: ADO
A28: HOT-NORTH EAST ZONE | B28: SAMASTIPUR | C28: 59 | D28: 5600 | E28: 1420 | F28: 143500 | G28: =+C28+E28 -> 1479 | H28: =+D28+F28 -> 149100 | I28: 0 | J28: 0 | K28: 28 | L28: 2800 | M28: =+I28+K28 -> 28 | N28: =+J28+L28 -> 2800
A29: HOT-North East Zone | B29: SITAMARHI&DARBHANGA | C29: 93 | D29: 8450 | E29: 4996 | F29: 600350 | G29: =+C29+E29 -> 5089 | H29: =+D29+F29 -> 608800 | I29: 4 | J29: 0 | K29: 108 | L29: 12800 | M29: =+I29+K29 -> 112 | N29: =+J29+L29 -> 12800
B30: Total | C30: 0 | D30: 0 | E30: 0 | F30: 0 | G30: 0 | H30: 0 | I30: 0 | J30: 0 | K30: 0 | L30: 0 | M30: 0 | N30: 0
A31: HOT-North East Zone | B31: EAST CHAMPARAN | C31: 1358 | D31: 109300 | E31: 6435 | F31: 644500 | G31: =+C31+E31 -> 7793 | H31: =+D31+F31 -> 753800 | I31: 2 | J31: 0 | K31: 38 | L31: 3800 | M31: =+I31+K31 -> 40 | N31: =+J31+L31 -> 3800 | O31: DDO
A32: HOT-North East Zone | B32: SARAN | C32: 1202 | D32: 120450 | E32: 10154 | F32: 1016150 | G32: =+C32+E32 -> 11356 | H32: =+D32+F32 -> 1136600 | I32: 1 | J32: 0 | K32: 65 | L32: 6500 | M32: =+I32+K32 -> 66 | N32: =+J32+L32 -> 6500
A33: HOT-North East Zone | B33: SIWAN | C33: 877 | D33: 64500 | E33: 9882 | F33: 995950 | G33: =+C33+E33 -> 10759 | H33: =+D33+F33 -> 1060450 | I33: 0 | J33: 0 | K33: 70 | L33: 7000 | M33: =+I33+K33 -> 70 | N33: =+J33+L33 -> 7000
B34: Total | C34: =SUM(C31:C33) -> 3437 | D34: =SUM(D31:D33) -> 294250 | E34: =SUM(E31:E33) -> 26471 | F34: =SUM(F31:F33) -> 2656600 | G34: =SUM(G31:G33) -> 29908 | H34: =SUM(H31:H33) -> 2950850 | I34: =SUM(I31:I33) -> 3 | J34: =SUM(J31:J33) -> 0 | ... N34: =SUM(N31:N33) -> 17300
B35: G Total | C35: =+C30+C34 -> 3437 | D35: =+D30+D34 -> 294250 | E35: =+E30+E34 -> 26471 | F35: =+F30+F34 -> 2656600 | G35: =+G30+G34 -> 29908 | H35: =+H30+H34 -> 2950850 | I35: =+I30+I34 -> 3 | J35: =+J30+J34 -> 0 | ... N35: =+N30+N34 -> 17300
A38: Zone OWN & BC Proposal Detail | C38: Total Proposal In BC | E38: Total Proposal Entry In BC on Date 01.01.2022 | G38: Total Proposal In OWN | I38: Total Proposal Entry In OWN on Date 24.01.2022 | K38: Grand Total Own+BC | M38: Grand Total Own+BC on Dated 24.01.2022
A39: zone | B39: DistrictName | C39: Num Clients | D39: Amount | E39: Num Clients | F39: Amount | G39: Num Clients | H39: Amount | I39: Num Clients | J39: Amount | K39: Num Clients | L39: Amount | M39: Num Clients | N39: Amount
A40: HOT-North East Zone | B40: MUZAFFARPUR | C40: 0 | D40: 0 | E40: 0 | F40: 0 | G40: 0 | H40: 0 | I40: 0 | J40: 0 | K40: =+C40+G40 -> 0 | L40: =+D40+H40 -> 0 | M40: =+E40+I40 -> 0 | N40: =+F40+J40 -> 0
A41: HOT-North East Zone | B41: SAMASTIPUR | C41: 0 | D41: 0 | E41: 0 | F41: 0 | G41: 0 | H41: 0 | I41: 0 | J41: 0 | K41: =+C41+G41 -> 0 | L41: =+D41+H41 -> 0 | M41: =+E41+I41 -> 0 | N41: =+F41+J41 -> 0
A42: HOT-NORTH EAST ZONE | B42: SITAMARHI&DARBHANGA | C42: 0 | D42: 0 | E42: 0 | F42: 0 | G42: 0 | H42: 0 | I42: 0 | J42: 0 | K42: =+C42+G42 -> 0 | L42: =+D42+H42 -> 0 | M42: =+E42+I42 -> 0 | N42: =+F42+J42 -> 0
...
